Workbook

Sheet Model Countries
A1: Government health spending as % of government spending, model countries (71), 2000-2023 (WHO GHED, GGHE-D % GGE)
A2: Abuja target | B2: 0.15 | C2: Grey cell = same value as the year before (likely carried forward by WHO, not a new figure). Blank = no WHO estimate. See Notes.
A4: Country | B4: ISO3 | C4: MOU 15 | D4: 2000 | E4: 2001 | F4: 2002 | G4: 2003 | H4: 2004 | I4: 2005 | J4: 2006 | K4: 2007 | L4: 2008 | M4: 2009 | N4: 2010 | O4: 2011 | P4: 2012 | Q4: 2013 | R4: 2014 | S4: 2015 | T4: 2016 | U4: 2017 | V4: 2018 | W4: 2019 | X4: 2020 | Y4: 2021 | Z4: 2022 | AA4: 2023 | AB4: 2024 | AC4: Latest | AD4: Latest Year | AE4: Avg 2019-2023 | AF4: Room to Abuja target
A5: Angola | B5: AGO | D5: 0.027385826 | E5: 0.059682546 | F5: 0.041912308 | G5: 0.04260468 | H5: 0.056592388 | I5: 0.048206377 | J5: 0.047187376 | K5: 0.045162711 | L5: 0.040603714 | M5: 0.057778893 | N5: 0.04249568 | O5: 0.045805688 | P5: 0.042015133 | Q5: 0.045754008 | R5: 0.036156802 | S5: 0.045626254 | T5: 0.054326968 | U5: 0.053643193 | V5: 0.053643193 | W5: 0.055068841 | X5: 0.073050218 | Y5: 0.087773657 | Z5: 0.06699635 | AA5: 0.058957567 | AC5: =LOOKUP(9.99E+307,D5:AB5) -> 0.058957567 | AD5: =LOOKUP(9.99E+307,D5:AB5,D$4:AB$4) -> 2023 | AE5: =IFERROR(AVERAGE(W5:AB5),"") -> 0.068369327 | AF5: =MAX(0,$B$2-AC5) -> 0.091042433
A6: Azerbaijan | B6: AZE | D6: 0.047502904 | E6: 0.047982063 | F6: 0.031931574 | G6: 0.035723515 | H6: 0.035575993 | I6: 0.039594917 | J6: 0.0342998 | K6: 0.034903398 | L6: 0.027519121 | M6: 0.032848394 | N6: 0.031712611 | O6: 0.028160138 | P6: 0.030453246 | Q6: 0.028222861 | R6: 0.031070068 | S6: 0.033728263 | T6: 0.03289871 | U6: 0.028237727 | V6: 0.026780353 | W6: 0.032879271 | X6: 0.057977181 | Y6: 0.046051784 | Z6: 0.036410747 | AA6: 0.042580843 | AC6: =LOOKUP(9.99E+307,D6:AB6) -> 0.042580843 | AD6: =LOOKUP(9.99E+307,D6:AB6,D$4:AB$4) -> 2023 | AE6: =IFERROR(AVERAGE(W6:AB6),"") -> 0.043179965 | AF6: =MAX(0,$B$2-AC6) -> 0.10741916
A7: Bangladesh | B7: BGD | D7: 0.052114644 | E7: 0.035785534 | F7: 0.045399313 | G7: 0.047553134 | H7: 0.048652663 | I7: 0.043888373 | J7: 0.047282033 | K7: 0.050751882 | L7: 0.038409143 | M7: 0.041153383 | N7: 0.044394164 | O7: 0.04181591 | P7: 0.040162044 | Q7: 0.036174552 | R7: 0.035924532 | S7: 0.033768887 | T7: 0.040993581 | U7: 0.041070523 | V7: 0.037503543 | W7: 0.026642132 | X7: 0.026732917 | Y7: 0.030042543 | Z7: 0.02623276 | AA7: 0.024716196 | AC7: =LOOKUP(9.99E+307,D7:AB7) -> 0.024716196 | AD7: =LOOKUP(9.99E+307,D7:AB7,D$4:AB$4) -> 2023 | AE7: =IFERROR(AVERAGE(W7:AB7),"") -> 0.02687331 | AF7: =MAX(0,$B$2-AC7) -> 0.1252838
A8: Belize | B8: BLZ | D8: 0.05847578 | E8: 0.068270483 | F8: 0.075145411 | G8: 0.071356831 | H8: 0.078819284 | I8: 0.083321724 | J8: 0.093324451 | K8: 0.10768107 | L8: 0.13384028 | M8: 0.12482731 | N8: 0.12763881 | O8: 0.12696217 | P8: 0.12936385 | Q8: 0.12273203 | R8: 0.12234224 | S8: 0.11345565 | T8: 0.12114573 | U8: 0.11624961 | V8: 0.12209848 | W8: 0.12076534 | X8: 0.11438439 | Y8: 0.13614674 | Z8: 0.11447968 | AA8: 0.1087746 | AC8: =LOOKUP(9.99E+307,D8:AB8) -> 0.1087746 | AD8: =LOOKUP(9.99E+307,D8:AB8,D$4:AB$4) -> 2023 | AE8: =IFERROR(AVERAGE(W8:AB8),"") -> 0.11891015 | AF8: =MAX(0,$B$2-AC8) -> 0.041225395
A9: Benin | B9: BEN | D9: 0.072511077 | E9: 0.077723508 | F9: 0.061315412 | G9: 0.076892033 | H9: 0.086366129 | I9: 0.074113364 | J9: 0.081737995 | K9: 0.060395412 | L9: 0.051033645 | M9: 0.051059413 | N9: 0.05344604 | O9: 0.044236145 | P9: 0.052463355 | Q9: 0.051338048 | R9: 0.040445924 | S9: 0.032547801 | T9: 0.046273146 | U9: 0.039717438 | V9: 0.040243492 | W9: 0.03124814 | X9: 0.026806235 | Y9: 0.01680898 | Z9: 0.025534043 | AA9: 0.025534043 | AC9: =LOOKUP(9.99E+307,D9:AB9) -> 0.025534043 | AD9: =LOOKUP(9.99E+307,D9:AB9,D$4:AB$4) -> 2023 | AE9: =IFERROR(AVERAGE(W9:AB9),"") -> 0.025186288 | AF9: =MAX(0,$B$2-AC9) -> 0.12446596
A10: Bolivia (Plurinational State of) | B10: BOL | D10: 0.082959833 | E10: 0.081801205 | F10: 0.078159523 | G10: 0.086116819 | H10: 0.078391628 | I10: 0.082987986 | J10: 0.087520018 | K10: 0.085002489 | L10: 0.076468911 | M10: 0.095118818 | N10: 0.097059021 | O10: 0.085434141 | P10: 0.083143749 | Q10: 0.092054644 | R10: 0.089520187 | S10: 0.096743507 | T10: 0.11075057 | U10: 0.11510429 | V10: 0.12721485 | W10: 0.13546631 | X10: 0.15777554 | Y10: 0.169198 | Z10: 0.12820347 | AA10: 0.12029774 | AC10: =LOOKUP(9.99E+307,D10:AB10) -> 0.12029774 | AD10: =LOOKUP(9.99E+307,D10:AB10,D$4:AB$4) -> 2023 | AE10: =IFERROR(AVERAGE(W10:AB10),"") -> 0.14218821 | AF10: =MAX(0,$B$2-AC10) -> 0.029702263
A11: Botswana | B11: BWA | C11: yes | D11: 0.08178297 | E11: 0.08178297 | F11: 0.08178297 | G11: 0.08178297 | H11: 0.08178297 | I11: 0.08178297 | J11: 0.08178297 | K11: 0.08178297 | L11: 0.076448069 | M11: 0.062520623 | N11: 0.08060935 | O11: 0.096322517 | P11: 0.10684479 | Q11: 0.11934482 | R11: 0.10958582 | S11: 0.10415888 | T11: 0.11211295 | U11: 0.14315475 | V11: 0.11542103 | W11: 0.12006065 | X11: 0.11661525 | Y11: 0.14610139 | Z11: 0.14610139 | AA11: 0.14610139 | AC11: =LOOKUP(9.99E+307,D11:AB11) -> 0.14610139 | AD11: =LOOKUP(9.99E+307,D11:AB11,D$4:AB$4) -> 2023 | AE11: =IFERROR(AVERAGE(W11:AB11),"") -> 0.13499601 | AF11: =MAX(0,$B$2-AC11) -> 0.0038986111
A12: Burkina Faso | B12: BFA | D12: 0.048483686 | E12: 0.049421768 | F12: 0.054349313 | G12: 0.055697293 | H12: 0.083909988 | I12: 0.060486403 | J12: 0.065406885 | K12: 0.062706828 | L12: 0.073215261 | M12: 0.07629394 | N12: 0.060323525 | O12: 0.065873938 | P12: 0.046960587 | Q12: 0.063829322 | R12: 0.077736711 | S12: 0.071526418 | T12: 0.11033994 | U12: 0.10235205 | V12: 0.087850237 | W12: 0.09576911 | X12: 0.116475 | Y12: 0.098384151 | Z12: 0.083968487 | AA12: 0.08775362 | AC12: =LOOKUP(9.99E+307,D12:AB12) -> 0.08775362 | AD12: =LOOKUP(9.99E+307,D12:AB12,D$4:AB$4) -> 2023 | AE12: =IFERROR(AVERAGE(W12:AB12),"") -> 0.096470074 | AF12: =MAX(0,$B$2-AC12) -> 0.06224638
A13: Burundi | B13: BDI | C13: yes | D13: 0.0594454 | E13: 0.066626387 | F13: 0.063795781 | G13: 0.037158155 | H13: 0.05803843 | I13: 0.06223104 | J13: 0.064814196 | K13: 0.063231559 | L13: 0.037877474 | M13: 0.054775238 | N13: 0.048606639 | O13: 0.082279139 | P13: 0.071102819 | Q13: 0.044317017 | R13: 0.097924833 | S13: 0.10443518 | T13: 0.099044924 | U13: 0.083575859 | V13: 0.079078622 | W13: 0.079078622 | X13: 0.073328781 | Y13: 0.073328781 | Z13: 0.047289734 | AA13: 0.047289734 | AC13: =LOOKUP(9.99E+307,D13:AB13) -> 0.047289734 | AD13: =LOOKUP(9.99E+307,D13:AB13,D$4:AB$4) -> 2023 | AE13: =IFERROR(AVERAGE(W13:AB13),"") -> 0.06406313 | AF13: =MAX(0,$B$2-AC13) -> 0.10271027
A14: Cambodia | B14: KHM | D14: 0.085917358 | E14: 0.07830318 | F14: 0.082978315 | G14: 0.094304419 | H14: 0.099010906 | I14: 0.098973665 | J14: 0.074111047 | K14: 0.067482748 | L14: 0.066590457 | M14: 0.059676833 | N14: 0.065196424 | O14: 0.062146068 | P14: 0.063306508 | Q14: 0.067916837 | R14: 0.061677031 | S14: 0.069401135 | T14: 0.068482499 | U14: 0.069959145 | V14: 0.075233431 | W14: 0.069910355 | X14: 0.068979673 | Y14: 0.14310493 | Z14: 0.064150882 | AA14: 0.066474256 | AC14: =LOOKUP(9.99E+307,D14:AB14) -> 0.066474256 | AD14: =LOOKUP(9.99E+307,D14:AB14,D$4:AB$4) -> 2023 | AE14: =IFERROR(AVERAGE(W14:AB14),"") -> 0.082524018 | AF14: =MAX(0,$B$2-AC14) -> 0.083525743
A15: Cameroon | B15: CMR | C15: yes | D15: 0.044262691 | E15: 0.053437476 | F15: 0.064329853 | G15: 0.06515377 | H15: 0.052618337 | I15: 0.05247488 | J15: 0.051831469 | K15: 0.042260818 | L15: 0.034610515 | M15: 0.030473874 | N15: 0.026757979 | O15: 0.032104812 | P15: 0.037318034 | Q15: 0.025009561 | R15: 0.029397316 | S15: 0.018129396 | T15: 0.018129396 | U15: 0.0073440903 | V15: 0.019570337 | W15: 0.021798592 | X15: 0.036595056 | Y15: 0.028629239 | Z15: 0.039128006 | AA15: 0.039128006 | AC15: =LOOKUP(9.99E+307,D15:AB15) -> 0.039128006 | AD15: =LOOKUP(9.99E+307,D15:AB15,D$4:AB$4) -> 2023 | AE15: =IFERROR(AVERAGE(W15:AB15),"") -> 0.033055779 | AF15: =MAX(0,$B$2-AC15) -> 0.11087199
A16: Central African Republic | B16: CAF | D16: 0.10021617 | E16: 0.10725758 | F16: 0.086075211 | G16: 0.1254863 | H16: 0.11276064 | I16: 0.064003949 | J16: 0.091779222 | K16: 0.098746586 | L16: 0.05283493 | M16: 0.04575438 | N16: 0.033414733 | O16: 0.029325564 | P16: 0.042233172 | Q16: 0.073451528 | R16: 0.039467859 | S16: 0.032645256 | T16: 0.049471331 | U16: 0.052599773 | V16: 0.039108746 | W16: 0.048423176 | X16: 0.048644204 | Y16: 0.064207349 | Z16: 0.084761972 | AA16: 0.084761972 | AC16: =LOOKUP(9.99E+307,D16:AB16) -> 0.084761972 | AD16: =LOOKUP(9.99E+307,D16:AB16,D$4:AB$4) -> 2023 | AE16: =IFERROR(AVERAGE(W16:AB16),"") -> 0.066159735 | AF16: =MAX(0,$B$2-AC16) -> 0.065238028
A17: Côte d'Ivoire | B17: CIV | D17: 0.045575986 | E17: 0.044565473 | F17: 0.041479588 | G17: 0.040670872 | H17: 0.041451526 | I17: 0.038913488 | J17: 0.038571844 | K17: 0.045792217 | L17: 0.046578813 | M17: 0.058213243 | N17: 0.058067884 | O17: 0.043936925 | P17: 0.046220031 | Q17: 0.045898829 | R17: 0.051112542 | S17: 0.048747077 | T17: 0.048519926 | U17: 0.051502876 | V17: 0.051172767 | W17: 0.056012759 | X17: 0.06538353 | Y17: 0.077738953 | Z17: 0.068222361 | AA17: 0.065832048 | AC17: =LOOKUP(9.99E+307,D17:AB17) -> 0.065832048 | AD17: =LOOKUP(9.99E+307,D17:AB17,D$4:AB$4) -> 2023 | AE17: =IFERROR(AVERAGE(W17:AB17),"") -> 0.06663793 | AF17: =MAX(0,$B$2-AC17) -> 0.084167952
A18: Democratic Republic of the Congo | B18: COD | D18: 0.024989526 | E18: 0.024989526 | F18: 0.024989526 | G18: 0.024989526 | H18: 0.024989526 | I18: 0.024989526 | J18: 0.024989526 | K18: 0.024989526 | L18: 0.024989526 | M18: 0.024989526 | N18: 0.024989526 | O18: 0.025320144 | P18: 0.038775921 | Q18: 0.039094405 | R18: 0.039867942 | S18: 0.041041536 | T18: 0.03807735 | U18: 0.038418849 | V18: 0.041669412 | W18: 0.041286588 | X18: 0.050872474 | Y18: 0.045126462 | Z18: 0.039843409 | AA18: 0.040007191 | AC18: =LOOKUP(9.99E+307,D18:AB18) -> 0.040007191 | AD18: =LOOKUP(9.99E+307,D18:AB18,D$4:AB$4) -> 2023 | AE18: =IFERROR(AVERAGE(W18:AB18),"") -> 0.043427225 | AF18: =MAX(0,$B$2-AC18) -> 0.10999281
A19: Djibouti | B19: DJI | D19: 0.060754762 | E19: 0.059684048 | F19: 0.05495636 | G19: 0.058153071 | H19: 0.053861504 | I19: 0.053278184 | J19: 0.072324629 | K19: 0.065265923 | L19: 0.063488808 | M19: 0.061399169 | N19: 0.069704871 | O19: 0.084744921 | P19: 0.071332936 | Q19: 0.067350478 | R19: 0.060729909 | S19: 0.040695095 | T19: 0.051373649 | U19: 0.048029952 | V19: 0.051697979 | W19: 0.051610975 | X19: 0.041593022 | Y19: 0.033152716 | Z19: 0.050955634 | AA19: 0.048918228 | AC19: =LOOKUP(9.99E+307,D19:AB19) -> 0.048918228 | AD19: =LOOKUP(9.99E+307,D19:AB19,D$4:AB$4) -> 2023 | AE19: =IFERROR(AVERAGE(W19:AB19),"") -> 0.045246115 | AF19: =MAX(0,$B$2-AC19) -> 0.10108177
A20: Dominican Republic | B20: DOM | D20: 0.12137587 | E20: 0.11438853 | F20: 0.10194515 | G20: 0.067342434 | H20: 0.06621449 | I20: 0.089872961 | J20: 0.082697029 | K20: 0.10323029 | L20: 0.11476502 | M20: 0.14433601 | N20: 0.15678899 | O20: 0.170697 | P20: 0.13968768 | Q20: 0.1503564 | R20: 0.14475961 | S20: 0.14195518 | T20: 0.15698118 | U20: 0.15108495 | V20: 0.15667871 | W20: 0.14952268 | X20: 0.14678337 | Y20: 0.18260876 | Z20: 0.15200764 | AA20: 0.15411339 | AC20: =LOOKUP(9.99E+307,D20:AB20) -> 0.15411339 | AD20: =LOOKUP(9.99E+307,D20:AB20,D$4:AB$4) -> 2023 | AE20: =IFERROR(AVERAGE(W20:AB20),"") -> 0.15700717 | AF20: =MAX(0,$B$2-AC20) -> 0
A21: Egypt | B21: EGY | D21: 0.066637259 | E21: 0.066326628 | F21: 0.061411839 | G21: 0.054432034 | H21: 0.052430897 | I21: 0.052435308 | J21: 0.050499468 | K21: 0.050176458 | L21: 0.046992469 | M21: 0.047180848 | N21: 0.043615632 | O21: 0.048270822 | P21: 0.043854094 | Q21: 0.041566329 | R21: 0.041614847 | S21: 0.050579767 | T21: 0.050579767 | U21: 0.054199476 | V21: 0.047215853 | W21: 0.048228469 | X21: 0.051611223 | Y21: 0.067994494 | Z21: 0.067607384 | AA21: 0.069267306 | AC21: =LOOKUP(9.99E+307,D21:AB21) -> 0.069267306 | AD21: =LOOKUP(9.99E+307,D21:AB21,D$4:AB$4) -> 2023 | AE21: =IFERROR(AVERAGE(W21:AB21),"") -> 0.060941775 | AF21: =MAX(0,$B$2-AC21) -> 0.080732694
A22: El Salvador | B22: SLV | D22: 0.18813766 | E22: 0.1768816 | F22: 0.1778229 | G22: 0.17186676 | H22: 0.18680647 | I22: 0.18938656 | J22: 0.19308365 | K22: 0.17984247 | L22: 0.16658825 | M22: 0.15814736 | N22: 0.17085518 | O22: 0.18986029 | P22: 0.162677 | Q22: 0.16716999 | R22: 0.16978041 | S22: 0.17738533 | T22: 0.17652054 | U22: 0.16314199 | V22: 0.16460562 | W22: 0.16971138 | X22: 0.1772464 | Y22: 0.2065045 | Z22: 0.21437885 | AA22: 0.1850918 | AC22: =LOOKUP(9.99E+307,D22:AB22) -> 0.1850918 | AD22: =LOOKUP(9.99E+307,D22:AB22,D$4:AB$4) -> 2023 | AE22: =IFERROR(AVERAGE(W22:AB22),"") -> 0.19058659 | AF22: =MAX(0,$B$2-AC22) -> 0
A23: Eswatini | B23: SWZ | C23: yes | D23: 0.097942724 | E23: 0.092848577 | F23: 0.091893816 | G23: 0.11396682 | H23: 0.097426119 | I23: 0.12612316 | J23: 0.12620983 | K23: 0.12373458 | L23: 0.13342635 | M23: 0.1333174 | N23: 0.13756534 | O23: 0.14277364 | P23: 0.12654774 | Q23: 0.11660085 | R23: 0.085009337 | S23: 0.085870171 | T23: 0.082180529 | U23: 0.099716406 | V23: 0.096976748 | W23: 0.1293036 | X23: 0.10393844 | Y23: 0.12300969 | Z23: 0.10635378 | AA23: 0.10635378 | AC23: =LOOKUP(9.99E+307,D23:AB23) -> 0.10635378 | AD23: =LOOKUP(9.99E+307,D23:AB23,D$4:AB$4) -> 2023 | AE23: =IFERROR(AVERAGE(W23:AB23),"") -> 0.11379186 | AF23: =MAX(0,$B$2-AC23) -> 0.043646221
A24: Ethiopia | B24: ETH | C24: yes | D24: 0.070295844 | E24: 0.089823351 | F24: 0.083686762 | G24: 0.084177933 | H24: 0.05726654 | I24: 0.07550024 | J24: 0.050760446 | K24: 0.064959817 | L24: 0.027417819 | M24: 0.053002 | N24: 0.051071138 | O24: 0.020911443 | P24: 0.064068546 | Q24: 0.061933026 | R24: 0.040883422 | S24: 0.055721168 | T24: 0.050244527 | U24: 0.047883601 | V24: 0.047606049 | W24: 0.047606049 | X24: 0.067922325 | Y24: 0.07096745 | Z24: 0.05676702 | AA24: 0.05676702 | AC24: =LOOKUP(9.99E+307,D24:AB24) -> 0.05676702 | AD24: =LOOKUP(9.99E+307,D24:AB24,D$4:AB$4) -> 2023 | AE24: =IFERROR(AVERAGE(W24:AB24),"") -> 0.060005973 | AF24: =MAX(0,$B$2-AC24) -> 0.09323298
A25: Fiji | B25: FJI | D25: 0.10588044 | E25: 0.079022274 | F25: 0.080357571 | G25: 0.086106272 | H25: 0.092540503 | I25: 0.10359533 | J25: 0.099688578 | K25: 0.10593208 | L25: 0.097818184 | M25: 0.083703699 | N25: 0.087944441 | O25: 0.074741101 | P25: 0.075050917 | Q25: 0.07466826 | R25: 0.071042762 | S25: 0.070441751 | T25: 0.066678991 | U25: 0.077232141 | V25: 0.077550287 | W25: 0.087279425 | X25: 0.086814642 | Y25: 0.10310143 | Z25: 0.10329376 | AA25: 0.09322113 | AC25: =LOOKUP(9.99E+307,D25:AB25) -> 0.09322113 | AD25: =LOOKUP(9.99E+307,D25:AB25,D$4:AB$4) -> 2023 | AE25: =IFERROR(AVERAGE(W25:AB25),"") -> 0.094742077 | AF25: =MAX(0,$B$2-AC25) -> 0.05677887
A26: Gambia | B26: GMB | D26: 0.063089752 | E26: 0.063089752 | F26: 0.063089752 | G26: 0.063089752 | H26: 0.063089752 | I26: 0.063089752 | J26: 0.063089752 | K26: 0.063089752 | L26: 0.063089752 | M26: 0.063089752 | N26: 0.063089752 | O26: 0.063089752 | P26: 0.063089752 | Q26: 0.063089752 | R26: 0.057540197 | S26: 0.050990448 | T26: 0.066577015 | U26: 0.044914708 | V26: 0.055134363 | W26: 0.053790603 | X26: 0.076984744 | Y26: 0.059844098 | Z26: 0.068301234 | AA26: 0.054587293 | AC26: =LOOKUP(9.99E+307,D26:AB26) -> 0.054587293 | AD26: =LOOKUP(9.99E+307,D26:AB26,D$4:AB$4) -> 2023 | AE26: =IFERROR(AVERAGE(W26:AB26),"") -> 0.062701594 | AF26: =MAX(0,$B$2-AC26) -> 0.095412707
A27: Ghana | B27: GHA | D27: 0.061019425 | E27: 0.061019425 | F27: 0.061019425 | G27: 0.077802806 | H27: 0.069171963 | I27: 0.13634508 | J27: 0.11497241 | K27: 0.097394896 | L27: 0.098777552 | M27: 0.12356558 | N27: 0.11915574 | O27: 0.12074167 | P27: 0.089727478 | Q27: 0.086166973 | R27: 0.067195373 | S27: 0.085578575 | T27: 0.065376787 | U27: 0.09274003 | V27: 0.065605044 | W27: 0.087683659 | X27: 0.080232305 | Y27: 0.077142072 | Z27: 0.074095879 | AA27: 0.10051485 | AC27: =LOOKUP(9.99E+307,D27:AB27) -> 0.10051485 | AD27: =LOOKUP(9.99E+307,D27:AB27,D$4:AB$4) -> 2023 | AE27: =IFERROR(AVERAGE(W27:AB27),"") -> 0.083933753 | AF27: =MAX(0,$B$2-AC27) -> 0.049485149
A28: Guatemala | B28: GTM | D28: 0.14082759 | E28: 0.144004 | F28: 0.14791301 | G28: 0.14208874 | H28: 0.15732374 | I28: 0.1420313 | J28: 0.14587105 | K28: 0.1423033 | L28: 0.15491264 | M28: 0.16026173 | N28: 0.14248166 | O28: 0.13759575 | P28: 0.14318863 | Q28: 0.15827068 | R28: 0.164603 | S28: 0.18107498 | T28: 0.18205315 | U28: 0.17212185 | V28: 0.16674454 | W28: 0.17651402 | X28: 0.15862992 | Y28: 0.19772802 | Z28: 0.1733054 | AA28: 0.1775436 | AC28: =LOOKUP(9.99E+307,D28:AB28) -> 0.1775436 | AD28: =LOOKUP(9.99E+307,D28:AB28,D$4:AB$4) -> 2023 | AE28: =IFERROR(AVERAGE(W28:AB28),"") -> 0.17674419 | AF28: =MAX(0,$B$2-AC28) -> 0
A29: Guinea | B29: GIN | D29: 0.023868253 | E29: 0.024863112 | F29: 0.044430332 | G29: 0.028638539 | H29: 0.01861527 | I29: 0.023775997 | J29: 0.018866088 | K29: 0.027802451 | L29: 0.026759889 | M29: 0.016039821 | N29: 0.017697701 | O29: 0.031844747 | P29: 0.02630034 | Q29: 0.026236229 | R29: 0.030479202 | S29: 0.019800686 | T29: 0.041296558 | U29: 0.034782426 | V29: 0.038791776 | W29: 0.061876755 | X29: 0.045516515 | Y29: 0.04510335 | Z29: 0.051174025 | AA29: 0.051174025 | AC29: =LOOKUP(9.99E+307,D29:AB29) -> 0.051174025 | AD29: =LOOKUP(9.99E+307,D29:AB29,D$4:AB$4) -> 2023 | AE29: =IFERROR(AVERAGE(W29:AB29),"") -> 0.050968934 | AF29: =MAX(0,$B$2-AC29) -> 0.098825974
A30: Guyana | B30: GUY | D30: 0.078165045 | E30: 0.067953935 | F30: 0.075090137 | G30: 0.073576484 | H30: 0.073529549 | I30: 0.062754049 | J30: 0.05696579 | K30: 0.066087761 | L30: 0.070215044 | M30: 0.074141932 | N30: 0.076051526 | O30: 0.086206064 | P30: 0.082260752 | Q30: 0.088188906 | R30: 0.094168501 | S30: 0.10840705 | T30: 0.10054208 | U30: 0.10613539 | V30: 0.10711576 | W30: 0.1032425 | X30: 0.13011635 | Y30: 0.12894853 | Z30: 0.085649328 | AA30: 0.073120976 | AC30: =LOOKUP(9.99E+307,D30:AB30) -> 0.073120976 | AD30: =LOOKUP(9.99E+307,D30:AB30,D$4:AB$4) -> 2023 | AE30: =IFERROR(AVERAGE(W30:AB30),"") -> 0.10421554 | AF30: =MAX(0,$B$2-AC30) -> 0.076879024
A31: Haiti | B31: HTI | D31: 0.13943684 | E31: 0.11909204 | F31: 0.073620429 | G31: 0.066061697 | H31: 0.079492502 | I31: 0.066687546 | J31: 0.02994277 | K31: 0.07113584 | L31: 0.074259653 | M31: 0.067716474 | N31: 0.064308343 | O31: 0.029842613 | P31: 0.027839146 | Q31: 0.029984677 | R31: 0.032014871 | S31: 0.044000373 | T31: 0.050224214 | U31: 0.045437198 | V31: 0.046750169 | W31: 0.042496586 | X31: 0.048419085 | Y31: 0.043947258 | Z31: 0.041084309 | AA31: 0.045637708 | AC31: =LOOKUP(9.99E+307,D31:AB31) -> 0.045637708 | AD31: =LOOKUP(9.99E+307,D31:AB31,D$4:AB$4) -> 2023 | AE31: =IFERROR(AVERAGE(W31:AB31),"") -> 0.044316989 | AF31: =MAX(0,$B$2-AC31) -> 0.10436229
A32: Honduras | B32: HND | D32: 0.13678985 | E32: 0.099386835 | F32: 0.094749918 | G32: 0.098826895 | H32: 0.095964127 | I32: 0.1236688 | J32: 0.13421832 | K32: 0.13636523 | L32: 0.12566714 | M32: 0.13993237 | N32: 0.13966723 | O32: 0.15026725 | P32: 0.12835978 | Q32: 0.11812871 | R32: 0.11553196 | S32: 0.11328797 | T32: 0.11295919 | U32: 0.10626307 | V32: 0.10892013 | W32: 0.11167437 | X32: 0.12344063 | Y32: 0.12092145 | Z32: 0.13315739 | AA32: 0.09428587 | AC32: =LOOKUP(9.99E+307,D32:AB32) -> 0.09428587 | AD32: =LOOKUP(9.99E+307,D32:AB32,D$4:AB$4) -> 2023 | AE32: =IFERROR(AVERAGE(W32:AB32),"") -> 0.11669594 | AF32: =MAX(0,$B$2-AC32) -> 0.05571413
A33: India | B33: IND | D33: 0.0305056 | E33: 0.029032168 | F33: 0.027712765 | G33: 0.026768761 | H33: 0.026527741 | I33: 0.029360442 | J33: 0.028859975 | K33: 0.027873428 | L33: 0.027989826 | M33: 0.031219337 | N33: 0.0311163 | O33: 0.033813007 | P33: 0.03438494 | Q33: 0.032388325 | R33: 0.032507055 | S33: 0.0337624 | T33: 0.033933346 | U33: 0.036608045 | V33: 0.036753218 | W33: 0.038472986 | X33: 0.036866047 | Y33: 0.044556293 | Z33: 0.047143903 | AA33: 0.045867086 | AC33: =LOOKUP(9.99E+307,D33:AB33) -> 0.045867086 | AD33: =LOOKUP(9.99E+307,D33:AB33,D$4:AB$4) -> 2023 | AE33: =IFERROR(AVERAGE(W33:AB33),"") -> 0.042581263 | AF33: =MAX(0,$B$2-AC33) -> 0.10413291
A34: Indonesia | B34: IDN | D34: 0.03592418 | E34: 0.039583151 | F34: 0.039828384 | G34: 0.044996161 | H34: 0.042014952 | I34: 0.042081809 | J34: 0.045113745 | K34: 0.054374208 | L34: 0.046298518 | M34: 0.054129438 | N34: 0.039148963 | O34: 0.039625185 | P34: 0.040733542 | Q34: 0.043404298 | R34: 0.054055018 | S34: 0.065787244 | T34: 0.081296864 | U34: 0.082089262 | V34: 0.084031391 | W34: 0.085453539 | X34: 0.10241962 | Y34: 0.12149899 | Z34: 0.080798512 | AA34: 0.08520731 | AC34: =LOOKUP(9.99E+307,D34:AB34) -> 0.08520731 | AD34: =LOOKUP(9.99E+307,D34:AB34,D$4:AB$4) -> 2023 | AE34: =IFERROR(AVERAGE(W34:AB34),"") -> 0.095075594 | AF34: =MAX(0,$B$2-AC34) -> 0.06479269
A35: Iraq | B35: IRQ | G35: 0.03131005 | H35: 0.029806504 | I35: 0.031964197 | J35: 0.030470798 | K35: 0.046332202 | L35: 0.041442576 | M35: 0.04733726 | N35: 0.048027453 | O35: 0.04798624 | P35: 0.023523643 | Q35: 0.023758931 | R35: 0.023695984 | S35: 0.016812644 | T35: 0.059849253 | U35: 0.047749205 | V35: 0.064310226 | W35: 0.059936714 | X35: 0.061605988 | Y35: 0.069839292 | Z35: 0.05841526 | AA35: 0.06184782 | AC35: =LOOKUP(9.99E+307,D35:AB35) -> 0.06184782 | AD35: =LOOKUP(9.99E+307,D35:AB35,D$4:AB$4) -> 2023 | AE35: =IFERROR(AVERAGE(W35:AB35),"") -> 0.062329015 | AF35: =MAX(0,$B$2-AC35) -> 0.08815218
A36: Jamaica | B36: JAM | D36: 0.11841487 | E36: 0.082009611 | F36: 0.086676102 | G36: 0.06137599 | H36: 0.076452746 | I36: 0.074342041 | J36: 0.062574463 | K36: 0.082274962 | L36: 0.083576364 | M36: 0.074510446 | N36: 0.090329323 | O36: 0.095287666 | P36: 0.091577921 | Q36: 0.10769291 | R36: 0.11251961 | S36: 0.1282022 | T36: 0.12683866 | U36: 0.13954786 | V36: 0.13039397 | W36: 0.13320455 | X36: 0.13988929 | Y36: 0.16177647 | Z36: 0.1896324 | AA36: 0.15855964 | AC36: =LOOKUP(9.99E+307,D36:AB36) -> 0.15855964 | AD36: =LOOKUP(9.99E+307,D36:AB36,D$4:AB$4) -> 2023 | AE36: =IFERROR(AVERAGE(W36:AB36),"") -> 0.15661247 | AF36: =MAX(0,$B$2-AC36) -> 0
A37: Jordan | B37: JOR | D37: 0.12689116 | E37: 0.136148 | F37: 0.133821 | G37: 0.1137037 | H37: 0.094005899 | I37: 0.11786743 | J37: 0.11360124 | K37: 0.12519184 | L37: 0.15125435 | M37: 0.17915905 | N37: 0.17020586 | O37: 0.15417559 | P37: 0.13670978 | Q37: 0.13126521 | R37: 0.13064031 | S37: 0.12219738 | T37: 0.1123799 | U37: 0.1109924 | V37: 0.099767199 | W37: 0.10080314 | X37: 0.10765898 | Y37: 0.10347293 | Z37: 0.10466299 | AA37: 0.10501314 | AC37: =LOOKUP(9.99E+307,D37:AB37) -> 0.10501314 | AD37: =LOOKUP(9.99E+307,D37:AB37,D$4:AB$4) -> 2023 | AE37: =IFERROR(AVERAGE(W37:AB37),"") -> 0.10432224 | AF37: =MAX(0,$B$2-AC37) -> 0.044986858
A38: Kenya | B38: KEN | C38: yes | D38: 0.070889826 | E38: 0.070889826 | F38: 0.070889826 | G38: 0.070224299 | H38: 0.069893775 | I38: 0.068923879 | J38: 0.068128095 | K38: 0.070393863 | L38: 0.07170805 | M38: 0.072007761 | N38: 0.072441263 | O38: 0.07981091 | P38: 0.073592792 | Q38: 0.071497207 | R38: 0.078450079 | S38: 0.080744801 | T38: 0.080254345 | U38: 0.067924047 | V38: 0.072187452 | W38: 0.082272358 | X38: 0.089104605 | Y38: 0.092824087 | Z38: 0.086511555 | AA38: 0.086511555 | AC38: =LOOKUP(9.99E+307,D38:AB38) -> 0.086511555 | AD38: =LOOKUP(9.99E+307,D38:AB38,D$4:AB$4) -> 2023 | AE38: =IFERROR(AVERAGE(W38:AB38),"") -> 0.087444832 | AF38: =MAX(0,$B$2-AC38) -> 0.063488445
A39: Kyrgyzstan | B39: KGZ | D39: 0.070640063 | E39: 0.071314993 | F39: 0.075632911 | G39: 0.080725298 | H39: 0.082125959 | I39: 0.13069867 | J39: 0.14458958 | K39: 0.10425051 | L39: 0.10385349 | M39: 0.10696233 | N39: 0.09203639 | O39: 0.098833132 | P39: 0.10400711 | Q39: 0.10346405 | R39: 0.071389055 | S39: 0.071201859 | T39: 0.064158077 | U39: 0.063416133 | V39: 0.073343763 | W39: 0.07093936 | X39: 0.069168787 | Y39: 0.09223444 | Z39: 0.075484381 | AA39: 0.073012633 | AC39: =LOOKUP(9.99E+307,D39:AB39) -> 0.073012633 | AD39: =LOOKUP(9.99E+307,D39:AB39,D$4:AB$4) -> 2023 | AE39: =IFERROR(AVERAGE(W39:AB39),"") -> 0.07616792 | AF39: =MAX(0,$B$2-AC39) -> 0.076987367
A40: Lao People's Democratic Republic | B40: LAO | D40: 0.061991444 | E40: 0.070550289 | F40: 0.061298442 | G40: 0.06834805 | H40: 0.05853271 | I40: 0.059141712 | J40: 0.043634644 | K40: 0.039029949 | L40: 0.031974592 | M40: 0.057037659 | N40: 0.026945555 | O40: 0.018174868 | P40: 0.017665906 | Q40: 0.029400711 | R40: 0.027363534 | S40: 0.033508019 | T40: 0.036279941 | U40: 0.040769591 | V40: 0.041973305 | W40: 0.05163249 | X40: 0.043148298 | Y40: 0.045797653 | Z40: 0.042535505 | AA40: 0.032051065 | AC40: =LOOKUP(9.99E+307,D40:AB40) -> 0.032051065 | AD40: =LOOKUP(9.99E+307,D40:AB40,D$4:AB$4) -> 2023 | AE40: =IFERROR(AVERAGE(W40:AB40),"") -> 0.043033002 | AF40: =MAX(0,$B$2-AC40) -> 0.11794893
A41: Lesotho | B41: LSO | C41: yes | D41: 0.074074073 | E41: 0.087013416 | F41: 0.077236958 | G41: 0.079082699 | H41: 0.082549896 | I41: 0.059969253 | J41: 0.070538449 | K41: 0.096424684 | L41: 0.080810175 | M41: 0.073227449 | N41: 0.071979928 | O41: 0.081988745 | P41: 0.096743116 | Q41: 0.10487746 | R41: 0.11592402 | S41: 0.10860278 | T41: 0.10336077 | U41: 0.11972834 | V41: 0.1077791 | W41: 0.12610546 | X41: 0.089495935 | Y41: 0.081524248 | Z41: 0.12883148 | AA41: 0.11833222 | AC41: =LOOKUP(9.99E+307,D41:AB41) -> 0.11833222 | AD41: =LOOKUP(9.99E+307,D41:AB41,D$4:AB$4) -> 2023 | AE41: =IFERROR(AVERAGE(W41:AB41),"") -> 0.10885787 | AF41: =MAX(0,$B$2-AC41) -> 0.031667776
...

Sheet All GHED Countries
A1: Government health spending as % of government spending, all WHO GHED countries (195), 2000-2023
A2: Abuja target | B2: ='Model Countries'!$B$2 -> 0.15 | C2: Grey cell = same value as the year before (likely carried forward by WHO, not a new figure). Blank = no WHO estimate. See Notes.
A4: Country | B4: ISO3 | C4: MOU 15 | D4: 2000 | E4: 2001 | F4: 2002 | G4: 2003 | H4: 2004 | I4: 2005 | J4: 2006 | K4: 2007 | L4: 2008 | M4: 2009 | N4: 2010 | O4: 2011 | P4: 2012 | Q4: 2013 | R4: 2014 | S4: 2015 | T4: 2016 | U4: 2017 | V4: 2018 | W4: 2019 | X4: 2020 | Y4: 2021 | Z4: 2022 | AA4: 2023 | AB4: 2024 | AC4: Latest | AD4: Latest Year | AE4: Avg 2019-2023 | AF4: Room to Abuja target
A5: Afghanistan | B5: AFG | F5: 0.01212456 | G5: 0.054576788 | H5: 0.036029682 | I5: 0.033812206 | J5: 0.027260592 | K5: 0.026107819 | L5: 0.030039206 | M5: 0.025147831 | N5: 0.022567358 | O5: 0.021881192 | P5: 0.013700027 | Q5: 0.017750696 | R5: 0.01860674 | S5: 0.02014406 | T5: 0.021411054 | U5: 0.023191156 | V5: 0.019090469 | W5: 0.017752601 | X5: 0.04246028 | Y5: 0.039610109 | Z5: 0.011260573 | AA5: 0.014601837 | AC5: =LOOKUP(9.99E+307,D5:AB5) -> 0.014601837 | AD5: =LOOKUP(9.99E+307,D5:AB5,D$4:AB$4) -> 2023 | AE5: =IFERROR(AVERAGE(W5:AB5),"") -> 0.02513708 | AF5: =MAX(0,$B$2-AC5) -> 0.13539816
A6: Albania | B6: ALB | D6: 0.08173727 | E6: 0.084236832 | F6: 0.082089748 | G6: 0.089971762 | H6: 0.09354475 | I6: 0.093009472 | J6: 0.090339222 | K6: 0.093771095 | L6: 0.072510648 | M6: 0.07217092 | N6: 0.080945129 | O6: 0.082909117 | P6: 0.086973457 | Q6: 0.088300629 | R6: 0.081742783 | S6: 0.08803566 | T6: 0.098886671 | U6: 0.095141821 | V6: 0.09886014 | W6: 0.10046225 | X6: 0.091851702 | Y6: 0.091411314 | Z6: 0.1230901 | AA6: 0.12282823 | AC6: =LOOKUP(9.99E+307,D6:AB6) -> 0.12282823 | AD6: =LOOKUP(9.99E+307,D6:AB6,D$4:AB$4) -> 2023 | AE6: =IFERROR(AVERAGE(W6:AB6),"") -> 0.10592872 | AF6: =MAX(0,$B$2-AC6) -> 0.027171774
A7: Algeria | B7: DZA | D7: 0.087792378 | E7: 0.092666121 | F7: 0.079734383 | G7: 0.09437788 | H7: 0.086691694 | I7: 0.077615991 | J7: 0.0784513 | K7: 0.076307364 | L7: 0.076872091 | M7: 0.086446848 | N7: 0.091878758 | O7: 0.090342512 | P7: 0.10061447 | Q7: 0.11701066 | R7: 0.11418038 | S7: 0.10604811 | T7: 0.10605941 | U7: 0.1060604 | V7: 0.10606169 | W7: 0.088303614 | X7: 0.088303061 | Y7: 0.088285294 | Z7: 0.05251564 | AA7: 0.061683345 | AC7: =LOOKUP(9.99E+307,D7:AB7) -> 0.061683345 | AD7: =LOOKUP(9.99E+307,D7:AB7,D$4:AB$4) -> 2023 | AE7: =IFERROR(AVERAGE(W7:AB7),"") -> 0.075818191 | AF7: =MAX(0,$B$2-AC7) -> 0.088316655
A8: Andorra | B8: AND | D8: 0.30418488 | E8: 0.18425966 | F8: 0.30313049 | G8: 0.30215126 | H8: 0.2770529 | I8: 0.18778881 | J8: 0.23288269 | K8: 0.21894827 | L8: 0.24805691 | M8: 0.16870777 | N8: 0.24528812 | O8: 0.2376627 | P8: 0.15370749 | Q8: 0.11189083 | R8: 0.2167169 | S8: 0.15752106 | T8: 0.11595967 | U8: 0.14120295 | V8: 0.14528497 | W8: 0.14574258 | X8: 0.1505597 | Y8: 0.15790538 | Z8: 0.15870918 | AA8: 0.15194997 | AC8: =LOOKUP(9.99E+307,D8:AB8) -> 0.15194997 | AD8: =LOOKUP(9.99E+307,D8:AB8,D$4:AB$4) -> 2023 | AE8: =IFERROR(AVERAGE(W8:AB8),"") -> 0.15297336 | AF8: =MAX(0,$B$2-AC8) -> 0
A9: Angola | B9: AGO | D9: 0.027385826 | E9: 0.059682546 | F9: 0.041912308 | G9: 0.04260468 | H9: 0.056592388 | I9: 0.048206377 | J9: 0.047187376 | K9: 0.045162711 | L9: 0.040603714 | M9: 0.057778893 | N9: 0.04249568 | O9: 0.045805688 | P9: 0.042015133 | Q9: 0.045754008 | R9: 0.036156802 | S9: 0.045626254 | T9: 0.054326968 | U9: 0.053643193 | V9: 0.053643193 | W9: 0.055068841 | X9: 0.073050218 | Y9: 0.087773657 | Z9: 0.06699635 | AA9: 0.058957567 | AC9: =LOOKUP(9.99E+307,D9:AB9) -> 0.058957567 | AD9: =LOOKUP(9.99E+307,D9:AB9,D$4:AB$4) -> 2023 | AE9: =IFERROR(AVERAGE(W9:AB9),"") -> 0.068369327 | AF9: =MAX(0,$B$2-AC9) -> 0.091042433
A10: Antigua and Barbuda | B10: ATG | D10: 0.11862532 | E10: 0.12117159 | F10: 0.10650884 | G10: 0.12448911 | H10: 0.12126567 | I10: 0.11530172 | J10: 0.08368083 | K10: 0.084518461 | L10: 0.080810614 | M10: 0.063313918 | N10: 0.13896391 | O10: 0.12989786 | P10: 0.14632363 | Q10: 0.13300732 | R10: 0.1510594 | S10: 0.11817538 | T10: 0.11606883 | U10: 0.11607389 | V10: 0.13074534 | W10: 0.11299994 | X10: 0.13783793 | Y10: 0.13094046 | Z10: 0.13773719 | AA10: 0.12279952 | AC10: =LOOKUP(9.99E+307,D10:AB10) -> 0.12279952 | AD10: =LOOKUP(9.99E+307,D10:AB10,D$4:AB$4) -> 2023 | AE10: =IFERROR(AVERAGE(W10:AB10),"") -> 0.12846301 | AF10: =MAX(0,$B$2-AC10) -> 0.027200479
A11: Argentina | B11: ARG | D11: 0.17819662 | E11: 0.16936325 | F11: 0.17747658 | G11: 0.1708437 | H11: 0.1493299 | I11: 0.16097414 | J11: 0.15193391 | K11: 0.14366702 | L11: 0.14556316 | M11: 0.16644169 | N11: 0.16697248 | O11: 0.16387676 | P11: 0.16684788 | Q11: 0.16740732 | R11: 0.1648708 | S11: 0.16445961 | T11: 0.15841621 | U11: 0.16251633 | V11: 0.15689699 | W11: 0.16311375 | X11: 0.16456453 | Y11: 0.16756962 | Z11: 0.15795045 | AA11: 0.16347298 | AC11: =LOOKUP(9.99E+307,D11:AB11) -> 0.16347298 | AD11: =LOOKUP(9.99E+307,D11:AB11,D$4:AB$4) -> 2023 | AE11: =IFERROR(AVERAGE(W11:AB11),"") -> 0.16333426 | AF11: =MAX(0,$B$2-AC11) -> 0
A12: Armenia | B12: ARM | D12: 0.038698921 | E12: 0.056626477 | F12: 0.053255291 | G12: 0.053752279 | H12: 0.06275475 | I12: 0.074400082 | J12: 0.07931859 | K12: 0.071985488 | L12: 0.06692462 | M12: 0.063449011 | N12: 0.064360886 | O12: 0.067010198 | P12: 0.070407543 | Q12: 0.0578088 | R12: 0.062752604 | S12: 0.06115303 | T12: 0.060535474 | U12: 0.052734718 | V12: 0.051338592 | W12: 0.056688504 | X12: 0.076896224 | Y12: 0.076349659 | Z12: 0.065027537 | AA12: 0.054564252 | AC12: =LOOKUP(9.99E+307,D12:AB12) -> 0.054564252 | AD12: =LOOKUP(9.99E+307,D12:AB12,D$4:AB$4) -> 2023 | AE12: =IFERROR(AVERAGE(W12:AB12),"") -> 0.065905235 | AF12: =MAX(0,$B$2-AC12) -> 0.095435748
A13: Australia | B13: AUS | D13: 0.14601329 | E13: 0.14708553 | F13: 0.15514163 | G13: 0.15481012 | H13: 0.15947051 | I13: 0.15902768 | J13: 0.15939968 | K13: 0.16490223 | L13: 0.15612955 | M13: 0.1588237 | N13: 0.16114603 | O13: 0.16322504 | P13: 0.16186937 | Q13: 0.15400936 | R13: 0.17636618 | S13: 0.18289017 | T13: 0.18542912 | U13: 0.18582108 | V13: 0.1852639 | W13: 0.17126518 | X13: 0.17063093 | Y13: 0.19292011 | Z13: 0.20248672 | AA13: 0.210086 | AC13: =LOOKUP(9.99E+307,D13:AB13) -> 0.210086 | AD13: =LOOKUP(9.99E+307,D13:AB13,D$4:AB$4) -> 2023 | AE13: =IFERROR(AVERAGE(W13:AB13),"") -> 0.18947779 | AF13: =MAX(0,$B$2-AC13) -> 0
A14: Austria | B14: AUT | D14: 0.13347214 | E14: 0.13241023 | F14: 0.13480156 | G14: 0.1356053 | H14: 0.12996217 | I14: 0.13645687 | J14: 0.13770193 | K14: 0.14055029 | L14: 0.14361295 | M14: 0.13751563 | N14: 0.13962966 | O14: 0.14304615 | P14: 0.1447297 | Q14: 0.14292957 | R14: 0.14502279 | S14: 0.14787659 | T14: 0.14904736 | U14: 0.15486373 | V14: 0.15766131 | W14: 0.16071058 | X14: 0.15197711 | Y14: 0.16888676 | Z14: 0.1632947 | AA14: 0.16192835 | AC14: =LOOKUP(9.99E+307,D14:AB14) -> 0.16192835 | AD14: =LOOKUP(9.99E+307,D14:AB14,D$4:AB$4) -> 2023 | AE14: =IFERROR(AVERAGE(W14:AB14),"") -> 0.1613595 | AF14: =MAX(0,$B$2-AC14) -> 0
A15: Azerbaijan | B15: AZE | D15: 0.047502904 | E15: 0.047982063 | F15: 0.031931574 | G15: 0.035723515 | H15: 0.035575993 | I15: 0.039594917 | J15: 0.0342998 | K15: 0.034903398 | L15: 0.027519121 | M15: 0.032848394 | N15: 0.031712611 | O15: 0.028160138 | P15: 0.030453246 | Q15: 0.028222861 | R15: 0.031070068 | S15: 0.033728263 | T15: 0.03289871 | U15: 0.028237727 | V15: 0.026780353 | W15: 0.032879271 | X15: 0.057977181 | Y15: 0.046051784 | Z15: 0.036410747 | AA15: 0.042580843 | AC15: =LOOKUP(9.99E+307,D15:AB15) -> 0.042580843 | AD15: =LOOKUP(9.99E+307,D15:AB15,D$4:AB$4) -> 2023 | AE15: =IFERROR(AVERAGE(W15:AB15),"") -> 0.043179965 | AF15: =MAX(0,$B$2-AC15) -> 0.10741916
A16: Bahamas | B16: BHS | D16: 0.13349923 | E16: 0.13963019 | F16: 0.13405273 | G16: 0.13809264 | H16: 0.13041773 | I16: 0.1286341 | J16: 0.12726217 | K16: 0.13499355 | L16: 0.1447345 | M16: 0.15009686 | N16: 0.15442394 | O16: 0.138966 | P16: 0.14060425 | Q16: 0.14021345 | R16: 0.1421291 | S16: 0.12836961 | T16: 0.13885354 | U16: 0.15596427 | V16: 0.143479 | W16: 0.14137413 | X16: 0.1491028 | Y16: 0.1232062 | Z16: 0.157634 | AA16: 0.13481312 | AC16: =LOOKUP(9.99E+307,D16:AB16) -> 0.13481312 | AD16: =LOOKUP(9.99E+307,D16:AB16,D$4:AB$4) -> 2023 | AE16: =IFERROR(AVERAGE(W16:AB16),"") -> 0.14122605 | AF16: =MAX(0,$B$2-AC16) -> 0.015186882
A17: Bahrain | B17: BHR | D17: 0.10268106 | E17: 0.090306454 | F17: 0.082211571 | G17: 0.087581797 | H17: 0.090417614 | I17: 0.091384249 | J17: 0.08944663 | K17: 0.090665274 | L17: 0.088342657 | M17: 0.11165728 | N17: 0.082303419 | O17: 0.080526104 | P17: 0.082980499 | Q17: 0.084568834 | R17: 0.10091253 | S17: 0.088659935 | T17: 0.085259905 | U17: 0.079766583 | V17: 0.072344513 | W17: 0.070605116 | X17: 0.082946186 | Y17: 0.090074635 | Z17: 0.086438742 | AA17: 0.084886742 | AC17: =LOOKUP(9.99E+307,D17:AB17) -> 0.084886742 | AD17: =LOOKUP(9.99E+307,D17:AB17,D$4:AB$4) -> 2023 | AE17: =IFERROR(AVERAGE(W17:AB17),"") -> 0.082990284 | AF17: =MAX(0,$B$2-AC17) -> 0.065113258
... A26: Bosnia and Herzegovina | B26: BIH | D26: 0.072539926 | E26: 0.086007443 | F26: 0.093225574 | G26: 0.11586452 | H26: 0.11320334 | I26: 0.10810091 | J26: 0.10958023 | K26: 0.1132833 | L26: 0.10918696 | M26: 0.12523983 | N26: 0.12600886 | O26: 0.13380139 | P26: 0.13883348 | Q26: 0.14794703 | R26: 0.14431893 | S26: 0.14984101 | T26: 0.15629663 | U26: 0.15466545 | V26: 0.151429 | W26: 0.15367926 | X26: 0.14880352 | Y26: 0.16057568 | Z26: 0.14565588 | AA26: 0.1442121 | AC26: =LOOKUP(9.99E+307,D26:AB26) -> 0.1442121 | AD26: =LOOKUP(9.99E+307,D26:AB26,D$4:AB$4) -> 2023 | AE26: =IFERROR(AVERAGE(W26:AB26),"") -> 0.15058529 | AF26: =MAX(0,$B$2-AC26) -> 0.0057878971
A27: Botswana | B27: BWA | C27: yes | D27: 0.08178297 | E27: 0.08178297 | F27: 0.08178297 | G27: 0.08178297 | H27: 0.08178297 | I27: 0.08178297 | J27: 0.08178297 | K27: 0.08178297 | L27: 0.076448069 | M27: 0.062520623 | N27: 0.08060935 | O27: 0.096322517 | P27: 0.10684479 | Q27: 0.11934482 | R27: 0.10958582 | S27: 0.10415888 | T27: 0.11211295 | U27: 0.14315475 | V27: 0.11542103 | W27: 0.12006065 | X27: 0.11661525 | Y27: 0.14610139 | Z27: 0.14610139 | AA27: 0.14610139 | AC27: =LOOKUP(9.99E+307,D27:AB27) -> 0.14610139 | AD27: =LOOKUP(9.99E+307,D27:AB27,D$4:AB$4) -> 2023 | AE27: =IFERROR(AVERAGE(W27:AB27),"") -> 0.13499601 | AF27: =MAX(0,$B$2-AC27) -> 0.0038986111
A28: Brazil | B28: BRA | D28: 0.096767397 | E28: 0.08826087 | F28: 0.082849064 | G28: 0.085001154 | H28: 0.087370558 | I28: 0.079895639 | J28: 0.083201942 | K28: 0.086356258 | L28: 0.087795753 | M28: 0.091458635 | N28: 0.090520887 | O28: 0.088034592 | P28: 0.085338993 | Q28: 0.089269133 | R28: 0.08928752 | S28: 0.083435726 | T28: 0.086763544 | U28: 0.089241323 | V28: 0.088030415 | W28: 0.091002769 | X28: 0.09034318 | Y28: 0.10667907 | Z28: 0.098047161 | AA28: 0.094769115 | AC28: =LOOKUP(9.99E+307,D28:AB28) -> 0.094769115 | AD28: =LOOKUP(9.99E+307,D28:AB28,D$4:AB$4) -> 2023 | AE28: =IFERROR(AVERAGE(W28:AB28),"") -> 0.096168259 | AF28: =MAX(0,$B$2-AC28) -> 0.055230885
A29: Brunei Darussalam | B29: BRN | D29: 0.057201023 | E29: 0.059716096 | F29: 0.051140027 | G29: 0.06989408 | H29: 0.063955154 | I29: 0.064329338 | J29: 0.058137608 | K29: 0.057738957 | L29: 0.062070947 | M29: 0.062168865 | N29: 0.05776835 | O29: 0.057430243 | P29: 0.054435349 | Q29: 0.051207418 | R29: 0.05203927 | S29: 0.058648925 | T29: 0.061532998 | U29: 0.05870759 | V29: 0.071402106 | W29: 0.06489933 | X29: 0.069482288 | Y29: 0.068214803 | Z29: 0.061809793 | AA29: 0.070233498 | AC29: =LOOKUP(9.99E+307,D29:AB29) -> 0.070233498 | AD29: =LOOKUP(9.99E+307,D29:AB29,D$4:AB$4) -> 2023 | AE29: =IFERROR(AVERAGE(W29:AB29),"") -> 0.066927942 | AF29: =MAX(0,$B$2-AC29) -> 0.079766502
A30: Bulgaria | B30: BGR | D30: 0.080766668 | E30: 0.094655161 | F30: 0.10744461 | G30: 0.11333193 | H30: 0.10827431 | I30: 0.11169881 | J30: 0.1079414 | K30: 0.091050682 | L30: 0.093931027 | M30: 0.090361624 | N30: 0.10849959 | O30: 0.11410629 | P30: 0.11179397 | Q30: 0.1069858 | R30: 0.10364101 | S30: 0.10233752 | T30: 0.11827792 | U30: 0.1183658 | V30: 0.11434177 | W30: 0.11553802 | X30: 0.12217266 | Y30: 0.13311139 | Z30: 0.11571726 | AA30: 0.12826755 | AC30: =LOOKUP(9.99E+307,D30:AB30) -> 0.12826755 | AD30: =LOOKUP(9.99E+307,D30:AB30,D$4:AB$4) -> 2023 | AE30: =IFERROR(AVERAGE(W30:AB30),"") -> 0.12296138 | AF30: =MAX(0,$B$2-AC30) -> 0.021732454
A31: Burkina Faso | B31: BFA | D31: 0.048483686 | E31: 0.049421768 | F31: 0.054349313 | G31: 0.055697293 | H31: 0.083909988 | I31: 0.060486403 | J31: 0.065406885 | K31: 0.062706828 | L31: 0.073215261 | M31: 0.07629394 | N31: 0.060323525 | O31: 0.065873938 | P31: 0.046960587 | Q31: 0.063829322 | R31: 0.077736711 | S31: 0.071526418 | T31: 0.11033994 | U31: 0.10235205 | V31: 0.087850237 | W31: 0.09576911 | X31: 0.116475 | Y31: 0.098384151 | Z31: 0.083968487 | AA31: 0.08775362 | AC31: =LOOKUP(9.99E+307,D31:AB31) -> 0.08775362 | AD31: =LOOKUP(9.99E+307,D31:AB31,D$4:AB$4) -> 2023 | AE31: =IFERROR(AVERAGE(W31:AB31),"") -> 0.096470074 | AF31: =MAX(0,$B$2-AC31) -> 0.06224638
A32: Burundi | B32: BDI | C32: yes | D32: 0.0594454 | E32: 0.066626387 | F32: 0.063795781 | G32: 0.037158155 | H32: 0.05803843 | I32: 0.06223104 | J32: 0.064814196 | K32: 0.063231559 | L32: 0.037877474 | M32: 0.054775238 | N32: 0.048606639 | O32: 0.082279139 | P32: 0.071102819 | Q32: 0.044317017 | R32: 0.097924833 | S32: 0.10443518 | T32: 0.099044924 | U32: 0.083575859 | V32: 0.079078622 | W32: 0.079078622 | X32: 0.073328781 | Y32: 0.073328781 | Z32: 0.047289734 | AA32: 0.047289734 | AC32: =LOOKUP(9.99E+307,D32:AB32) -> 0.047289734 | AD32: =LOOKUP(9.99E+307,D32:AB32,D$4:AB$4) -> 2023 | AE32: =IFERROR(AVERAGE(W32:AB32),"") -> 0.06406313 | AF32: =MAX(0,$B$2-AC32) -> 0.10271027
A33: Cabo Verde | B33: CPV | D33: 0.075015879 | E33: 0.11173052 | F33: 0.095042782 | G33: 0.11367002 | H33: 0.096314259 | I33: 0.088029909 | J33: 0.089211149 | K33: 0.10090197 | L33: 0.081084881 | M33: 0.08311655 | N33: 0.072267523 | O33: 0.086077766 | P33: 0.088649693 | Q33: 0.090295563 | R33: 0.099830713 | S33: 0.10093954 | T33: 0.10392425 | U33: 0.091237488 | V33: 0.11265527 | W33: 0.11783461 | X33: 0.13447078 | Y33: 0.14889709 | Z33: 0.1606422 | AA33: 0.1378945 | AC33: =LOOKUP(9.99E+307,D33:AB33) -> 0.1378945 | AD33: =LOOKUP(9.99E+307,D33:AB33,D$4:AB$4) -> 2023 | AE33: =IFERROR(AVERAGE(W33:AB33),"") -> 0.13994784 | AF33: =MAX(0,$B$2-AC33) -> 0.012105503
A34: Cambodia | B34: KHM | D34: 0.085917358 | E34: 0.07830318 | F34: 0.082978315 | G34: 0.094304419 | H34: 0.099010906 | I34: 0.098973665 | J34: 0.074111047 | K34: 0.067482748 | L34: 0.066590457 | M34: 0.059676833 | N34: 0.065196424 | O34: 0.062146068 | P34: 0.063306508 | Q34: 0.067916837 | R34: 0.061677031 | S34: 0.069401135 | T34: 0.068482499 | U34: 0.069959145 | V34: 0.075233431 | W34: 0.069910355 | X34: 0.068979673 | Y34: 0.14310493 | Z34: 0.064150882 | AA34: 0.066474256 | AC34: =LOOKUP(9.99E+307,D34:AB34) -> 0.066474256 | AD34: =LOOKUP(9.99E+307,D34:AB34,D$4:AB$4) -> 2023 | AE34: =IFERROR(AVERAGE(W34:AB34),"") -> 0.082524018 | AF34: =MAX(0,$B$2-AC34) -> 0.083525743
A35: Cameroon | B35: CMR | C35: yes | D35: 0.044262691 | E35: 0.053437476 | F35: 0.064329853 | G35: 0.06515377 | H35: 0.052618337 | I35: 0.05247488 | J35: 0.051831469 | K35: 0.042260818 | L35: 0.034610515 | M35: 0.030473874 | N35: 0.026757979 | O35: 0.032104812 | P35: 0.037318034 | Q35: 0.025009561 | R35: 0.029397316 | S35: 0.018129396 | T35: 0.018129396 | U35: 0.0073440903 | V35: 0.019570337 | W35: 0.021798592 | X35: 0.036595056 | Y35: 0.028629239 | Z35: 0.039128006 | AA35: 0.039128006 | AC35: =LOOKUP(9.99E+307,D35:AB35) -> 0.039128006 | AD35: =LOOKUP(9.99E+307,D35:AB35,D$4:AB$4) -> 2023 | AE35: =IFERROR(AVERAGE(W35:AB35),"") -> 0.033055779 | AF35: =MAX(0,$B$2-AC35) -> 0.11087199
A36: Canada | B36: CAN | D36: 0.14815627 | E36: 0.1527648 | F36: 0.15882566 | G36: 0.16363544 | H36: 0.16926079 | I36: 0.17131039 | J36: 0.16781704 | K36: 0.17068182 | L36: 0.1728191 | M36: 0.17325489 | N36: 0.17377098 | O36: 0.17589609 | P36: 0.18173801 | Q36: 0.18530561 | R36: 0.18969894 | S36: 0.19068136 | T36: 0.18961018 | U36: 0.18809015 | V36: 0.18701818 | W36: 0.18927599 | X36: 0.18363117 | Y36: 0.19796778 | Z36: 0.19361433 | AA36: 0.18684921 | AB36: 0.17756598 | AC36: =LOOKUP(9.99E+307,D36:AB36) -> 0.17756598 | AD36: =LOOKUP(9.99E+307,D36:AB36,D$4:AB$4) -> 2024 | AE36: =IFERROR(AVERAGE(W36:AB36),"") -> 0.18815074 | AF36: =MAX(0,$B$2-AC36) -> 0
A37: Central African Republic | B37: CAF | D37: 0.10021617 | E37: 0.10725758 | F37: 0.086075211 | G37: 0.1254863 | H37: 0.11276064 | I37: 0.064003949 | J37: 0.091779222 | K37: 0.098746586 | L37: 0.05283493 | M37: 0.04575438 | N37: 0.033414733 | O37: 0.029325564 | P37: 0.042233172 | Q37: 0.073451528 | R37: 0.039467859 | S37: 0.032645256 | T37: 0.049471331 | U37: 0.052599773 | V37: 0.039108746 | W37: 0.048423176 | X37: 0.048644204 | Y37: 0.064207349 | Z37: 0.084761972 | AA37: 0.084761972 | AC37: =LOOKUP(9.99E+307,D37:AB37) -> 0.084761972 | AD37: =LOOKUP(9.99E+307,D37:AB37,D$4:AB$4) -> 2023 | AE37: =IFERROR(AVERAGE(W37:AB37),"") -> 0.066159735 | AF37: =MAX(0,$B$2-AC37) -> 0.065238028
A38: Chad | B38: TCD | D38: 0.11398789 | E38: 0.11868776 | F38: 0.11724425 | G38: 0.089815569 | H38: 0.1503138 | I38: 0.12423414 | J38: 0.07144639 | K38: 0.059949446 | L38: 0.042314992 | M38: 0.035498657 | N38: 0.034979272 | O38: 0.036880267 | P38: 0.039646971 | Q38: 0.050367928 | R38: 0.055486155 | S38: 0.052452025 | T38: 0.057250209 | U38: 0.046783958 | V38: 0.048614955 | W38: 0.048614955 | X38: 0.039544351 | Y38: 0.05641912 | Z38: 0.072637334 | AA38: 0.072637334 | AC38: =LOOKUP(9.99E+307,D38:AB38) -> 0.072637334 | AD38: =LOOKUP(9.99E+307,D38:AB38,D$4:AB$4) -> 2023 | AE38: =IFERROR(AVERAGE(W38:AB38),"") -> 0.057970619 | AF38: =MAX(0,$B$2-AC38) -> 0.077362666
A39: Chile | B39: CHL | D39: 0.10956289 | E39: 0.11133472 | F39: 0.1166363 | G39: 0.12481333 | H39: 0.13101777 | I39: 0.12869405 | J39: 0.13405399 | K39: 0.1359831 | L39: 0.13461457 | M39: 0.13603492 | N39: 0.13689023 | O39: 0.14010506 | P39: 0.14573092 | Q39: 0.15411278 | R39: 0.15693084 | S39: 0.1602235 | T39: 0.16750845 | U39: 0.17972158 | V39: 0.18303989 | W39: 0.18011597 | X39: 0.18839195 | Y39: 0.15523948 | Z39: 0.19047033 | AA39: 0.1916633 | AB39: 0.19296413 | AC39: =LOOKUP(9.99E+307,D39:AB39) -> 0.19296413 | AD39: =LOOKUP(9.99E+307,D39:AB39,D$4:AB$4) -> 2024 | AE39: =IFERROR(AVERAGE(W39:AB39),"") -> 0.18314086 | AF39: =MAX(0,$B$2-AC39) -> 0
A40: China | B40: CHN | D40: 0.060898409 | E40: 0.05589242 | F40: 0.060258031 | G40: 0.068765297 | H40: 0.072660584 | I40: 0.074888291 | J40: 0.075638208 | K40: 0.079013572 | L40: 0.077085824 | M40: 0.083752317 | N40: 0.087509222 | O40: 0.0860285 | P40: 0.090372934 | Q40: 0.094168425 | R40: 0.096608858 | S40: 0.094190235 | T40: 0.089527655 | U40: 0.087973442 | V40: 0.087614632 | W40: 0.087695618 | X40: 0.086463261 | Y40: 0.089053545 | Z40: 0.10394173 | AA40: 0.10367977 | AC40: =LOOKUP(9.99E+307,D40:AB40) -> 0.10367977 | AD40: =LOOKUP(9.99E+307,D40:AB40,D$4:AB$4) -> 2023 | AE40: =IFERROR(AVERAGE(W40:AB40),"") -> 0.094166784 | AF40: =MAX(0,$B$2-AC40) -> 0.046320229
A41: Colombia | B41: COL | D41: 0.14881617 | E41: 0.15377504 | F41: 0.1486478 | G41: 0.15598855 | H41: 0.15737347 | I41: 0.16830919 | J41: 0.16057571 | K41: 0.16284443 | L41: 0.16693029 | M41: 0.17040621 | N41: 0.1682774 | O41: 0.16484554 | P41: 0.16199553 | Q41: 0.16341106 | R41: 0.16182764 | S41: 0.17037544 | T41: 0.1765918 | U41: 0.18604675 | V41: 0.15547496 | W41: 0.16659067 | X41: 0.18450232 | Y41: 0.19372189 | Z41: 0.1576685 | AA41: 0.16186947 | AB41: 0.17243502 | AC41: =LOOKUP(9.99E+307,D41:AB41) -> 0.17243502 | AD41: =LOOKUP(9.99E+307,D41:AB41,D$4:AB$4) -> 2024 | AE41: =IFERROR(AVERAGE(W41:AB41),"") -> 0.17279798 | AF41: =MAX(0,$B$2-AC41) -> 0
A42: Comoros | B42: COM | D42: 0.091551466 | E42: 0.041141682 | F42: 0.067107038 | G42: 0.066844735 | H42: 0.067557421 | I42: 0.054200544 | J42: 0.051817398 | K42: 0.043323989 | L42: 0.028645396 | M42: 0.027746561 | N42: 0.02839236 | O42: 0.072384434 | P42: 0.053522482 | Q42: 0.04449965 | R42: 0.038196549 | S42: 0.024457152 | T42: 0.030360751 | U42: 0.03585496 | V42: 0.039939125 | W42: 0.041334567 | X42: 0.068890824 | Y42: 0.047373166 | Z42: 0.047373166 | AA42: 0.047373166 | AC42: =LOOKUP(9.99E+307,D42:AB42) -> 0.047373166 | AD42: =LOOKUP(9.99E+307,D42:AB42,D$4:AB$4) -> 2023 | AE42: =IFERROR(AVERAGE(W42:AB42),"") -> 0.050468978 | AF42: =MAX(0,$B$2-AC42) -> 0.10262683
A43: Congo | B43: COG | D43: 0.022729034 | E43: 0.033190191 | F43: 0.013442719 | G43: 0.018552579 | H43: 0.017842994 | I43: 0.019531525 | J43: 0.020837886 | K43: 0.020520797 | L43: 0.045489221 | M43: 0.025281646 | N43: 0.03602102 | O43: 0.023368313 | P43: 0.026713102 | Q43: 0.022095163 | R43: 0.019499675 | S43: 0.027098103 | T43: 0.028850231 | U43: 0.034111474 | V43: 0.034871991 | W43: 0.051072521 | X43: 0.082168407 | Y43: 0.082168407 | Z43: 0.035258799 | AA43: 0.054217749 | AC43: =LOOKUP(9.99E+307,D43:AB43) -> 0.054217749 | AD43: =LOOKUP(9.99E+307,D43:AB43,D$4:AB$4) -> 2023 | AE43: =IFERROR(AVERAGE(W43:AB43),"") -> 0.060977177 | AF43: =MAX(0,$B$2-AC43) -> 0.095782251
A44: Cook Islands | B44: COK | D44: 0.096333189 | E44: 0.09633318 | F44: 0.10124437 | G44: 0.09633317 | H44: 0.09633316 | I44: 0.09633316 | J44: 0.096311035 | K44: 0.096309767 | L44: 0.096322861 | M44: 0.10858501 | N44: 0.095378628 | O44: 0.088194342 | P44: 0.083177214 | Q44: 0.080714674 | R44: 0.091433182 | S44: 0.072444553 | T44: 0.081484423 | U44: 0.072633815 | V44: 0.076654878 | W44: 0.093362999 | X44: 0.11665719 | Y44: 0.082263794 | Z44: 0.10750381 | AA44: 0.1027783 | AC44: =LOOKUP(9.99E+307,D44:AB44) -> 0.1027783 | AD44: =LOOKUP(9.99E+307,D44:AB44,D$4:AB$4) -> 2023 | AE44: =IFERROR(AVERAGE(W44:AB44),"") -> 0.10051322 | AF44: =MAX(0,$B$2-AC44) -> 0.047221699
A45: Costa Rica | B45: CRI | D45: 0.25264774 | E45: 0.24561287 | F45: 0.24758076 | G45: 0.26331982 | H45: 0.25737473 | I45: 0.26825884 | J45: 0.30262608 | K45: 0.31738693 | L45: 0.33367374 | M45: 0.33472801 | N45: 0.32182404 | O45: 0.33184631 | P45: 0.31732821 | Q45: 0.29452593 | R45: 0.2958095 | S45: 0.29424847 | T45: 0.28605955 | U45: 0.27034313 | V45: 0.27914709 | W45: 0.24153326 | X45: 0.25207146 | Y45: 0.257729 | Z45: 0.25816147 | AA45: 0.24907295 | AC45: =LOOKUP(9.99E+307,D45:AB45) -> 0.24907295 | AD45: =LOOKUP(9.99E+307,D45:AB45,D$4:AB$4) -> 2023 | AE45: =IFERROR(AVERAGE(W45:AB45),"") -> 0.25171363 | AF45: =MAX(0,$B$2-AC45) -> 0
A46: Croatia | B46: HRV | D46: 0.11923579 | E46: 0.1164405 | F46: 0.098688946 | G46: 0.10316412 | H46: 0.10597341 | I46: 0.12509827 | J46: 0.13114732 | K46: 0.13788143 | L46: 0.13838007 | M46: 0.13517841 | N46: 0.13775545 | O46: 0.12867774 | P46: 0.13348791 | Q46: 0.11375049 | R46: 0.11334707 | S46: 0.11636552 | T46: 0.12088621 | U46: 0.12407314 | V46: 0.12274974 | W46: 0.1195514 | X46: 0.1170918 | Y46: 0.14128839 | Z46: 0.13709288 | AA46: 0.12840257 | AC46: =LOOKUP(9.99E+307,D46:AB46) -> 0.12840257 | AD46: =LOOKUP(9.99E+307,D46:AB46,D$4:AB$4) -> 2023 | AE46: =IFERROR(AVERAGE(W46:AB46),"") -> 0.12868541 | AF46: =MAX(0,$B$2-AC46) -> 0.021597433
A47: Cuba | B47: CUB | D47: 0.10802315 | E47: 0.11391795 | F47: 0.11190471 | G47: 0.10890823 | H47: 0.10320927 | I47: 0.11667609 | J47: 0.11205644 | K47: 0.1448143 | L47: 0.13177696 | M47: 0.14932304 | N47: 0.13865822 | O47: 0.15093541 | P47: 0.11494596 | Q47: 0.14140575 | R47: 0.18024471 | S47: 0.18245586 | T47: 0.17302824 | U47: 0.15512218 | V47: 0.14935592 | W47: 0.15516299 | X47: 0.16431042 | Y47: 0.21482759 | Z47: 0.21039637 | AA47: 0.1997772 | AC47: =LOOKUP(9.99E+307,D47:AB47) -> 0.1997772 | AD47: =LOOKUP(9.99E+307,D47:AB47,D$4:AB$4) -> 2023 | AE47: =IFERROR(AVERAGE(W47:AB47),"") -> 0.18889491 | AF47: =MAX(0,$B$2-AC47) -> 0
A48: Cyprus | B48: CYP | D48: 0.059856963 | E48: 0.060168471 | F48: 0.06400969 | G48: 0.057754579 | H48: 0.054583502 | I48: 0.054313054 | J48: 0.057055769 | K48: 0.057653775 | L48: 0.061328058 | M48: 0.061237974 | N48: 0.066829467 | O48: 0.067843671 | P48: 0.055008144 | Q48: 0.068120861 | R48: 0.056516542 | S48: 0.066295128 | T48: 0.07054956 | U48: 0.071307569 | V48: 0.064431195 | W48: 0.094155998 | X48: 0.13524846 | Y48: 0.16323246 | Z48: 0.1659008 | AA48: 0.14859171 | AC48: =LOOKUP(9.99E+307,D48:AB48) -> 0.14859171 | AD48: =LOOKUP(9.99E+307,D48:AB48,D$4:AB$4) -> 2023 | AE48: =IFERROR(AVERAGE(W48:AB48),"") -> 0.14142589 | AF48: =MAX(0,$B$2-AC48) -> 0.0014082909
A49: Czechia | B49: CZE | D49: 0.12388258 | E49: 0.11838051 | F49: 0.12182892 | G49: 0.1161949 | H49: 0.13144728 | I49: 0.1275457 | J49: 0.12711453 | K49: 0.12403005 | L49: 0.12545538 | M49: 0.13544696 | N49: 0.14695007 | O49: 0.14741914 | P49: 0.14378068 | Q49: 0.14843148 | R49: 0.14962428 | S49: 0.14754028 | T49: 0.15715848 | U49: 0.15912028 | V49: 0.15556313 | W49: 0.15682148 | X49: 0.17062262 | Y49: 0.17588268 | Z49: 0.16703617 | AA49: 0.16180204 | AC49: =LOOKUP(9.99E+307,D49:AB49) -> 0.16180204 | AD49: =LOOKUP(9.99E+307,D49:AB49,D$4:AB$4) -> 2023 | AE49: =IFERROR(AVERAGE(W49:AB49),"") -> 0.166433 | AF49: =MAX(0,$B$2-AC49) -> 0
...

Sheet Spending by Category
A1: Government spending by category, % of total outlays (IMF Government Finance Statistics, COFOG), 46 countries, 2005-2025
A2: One row per country-year with data. Health = sum of its sub-items (formula). Total should be 100%. WHO Health Share = the GHED figure for the same year from the 'All GHED Countries' sheet, for comparison.
A4: Country | B4: ISO3 | C4: MOU 15 | D4: Year | E4: Coverage | F4: General Public Services (excl. Interest) | G4: Interest on Public Debt | H4: Defence | I4: Public Order and Safety | J4: Economic Affairs | K4: Environmental Protection | L4: Housing and Community Amenities | M4: Health | N4: Recreation, Culture and Religion | O4: Education | P4: Social Protection | Q4: Unclassified | R4: Total | S4: Medical Products | T4: Outpatient Services | U4: Hospital Services | V4: Public Health Services | W4: Health R&D | X4: Other Health | Y4: Health (No Breakdown) | Z4: WHO Health Share (GHED)
A5: Angola | B5: AGO | D5: 2014 | E5: Central government (budgetary) | F5: 0.21134662 | G5: 0.024892133 | H5: 0.11372186 | I5: 0.086392824 | J5: 0.19236299 | K5: 0.0062704669 | L5: 0.093350513 | M5: =SUM(S5:Y5) -> 0.046716281 | N5: 0.012095067 | O5: 0.068522597 | P5: 0.14432865 | R5: =SUM(F5:Q5) -> 1 | S5: 0.00073846322 | T5: 0.00087491207 | U5: 0.034201646 | V5: 0.01090126 | W5: 0 | X5: 0 | Z5: =IFERROR(IF(INDEX('All GHED Countries'!$D$5:$AB$199,MATCH($B5,'All GHED Countries'!$B$5:$B$199,0),MATCH($D5,'All GHED Countries'!$D$4:$AB$4,0))="","",INDEX('All GHED Countries'!$D$5:$AB$199,MATCH($B5,'All GHED Countries'!$B$5:$B$199,0),MATCH($D5,'All GHED Countries'!$D$4:$AB$4,0))),"") -> 0.036156802
A6: Angola | B6: AGO | D6: 2015 | E6: Central government (budgetary) | F6: 0.13209355 | G6: 0.071528649 | H6: 0.22712454 | I6: 0.04583937 | J6: 0.12396567 | K6: 0.0061437895 | L6: 0.050239753 | M6: =SUM(S6:Y6) -> 0.055617432 | N6: 0.0098367568 | O6: 0.12100889 | P6: 0.15660161 | R6: =SUM(F6:Q6) -> 1 | S6: 0.0010024234 | T6: 0.00074248199 | U6: 0.037021308 | V6: 0.016851218 | W6: 0 | X6: 0 | Z6: =IFERROR(IF(INDEX('All GHED Countries'!$D$5:$AB$199,MATCH($B6,'All GHED Countries'!$B$5:$B$199,0),MATCH($D6,'All GHED Countries'!$D$4:$AB$4,0))="","",INDEX('All GHED Countries'!$D$5:$AB$199,MATCH($B6,'All GHED Countries'!$B$5:$B$199,0),MATCH($D6,'All GHED Countries'!$D$4:$AB$4,0))),"") -> 0.045626254
A7: Angola | B7: AGO | D7: 2016 | E7: Central government (budgetary) | F7: 0.14559431 | G7: 0.10094723 | H7: 0.14380666 | I7: 0.13245054 | J7: 0.16789042 | K7: 0.00053985518 | L7: 0.034355169 | M7: =SUM(S7:Y7) -> 0.055828603 | N7: 0.0050662721 | O7: 0.10821701 | P7: 0.10530394 | R7: =SUM(F7:Q7) -> 1 | S7: 0.00085143784 | T7: 0.00090584734 | U7: 0.034584982 | V7: 0.019486336 | W7: 0 | X7: 0 | Z7: =IFERROR(IF(INDEX('All GHED Countries'!$D$5:$AB$199,MATCH($B7,'All GHED Countries'!$B$5:$B$199,0),MATCH($D7,'All GHED Countries'!$D$4:$AB$4,0))="","",INDEX('All GHED Countries'!$D$5:$AB$199,MATCH($B7,'All GHED Countries'!$B$5:$B$199,0),MATCH($D7,'All GHED Countries'!$D$4:$AB$4,0))),"") -> 0.054326968
A8: Angola | B8: AGO | D8: 2017 | E8: Central government (budgetary) | F8: 0.14598649 | G8: 0.11692908 | H8: 0.13153489 | I8: 0.10753201 | J8: 0.19782268 | K8: 0.005633868 | L8: 0.063749089 | M8: =SUM(S8:Y8) -> 0.044905958 | N8: 0.0078327547 | O8: 0.087602969 | P8: 0.09047021 | R8: =SUM(F8:Q8) -> 1 | S8: 0.0020233046 | T8: 5.2756844e-05 | U8: 0.029246367 | V8: 0.01358353 | W8: 0 | X8: 0 | Z8: =IFERROR(IF(INDEX('All GHED Countries'!$D$5:$AB$199,MATCH($B8,'All GHED Countries'!$B$5:$B$199,0),MATCH($D8,'All GHED Countries'!$D$4:$AB$4,0))="","",INDEX('All GHED Countries'!$D$5:$AB$199,MATCH($B8,'All GHED Countries'!$B$5:$B$199,0),MATCH($D8,'All GHED Countries'!$D$4:$AB$4,0))),"") -> 0.053643193
A9: Angola | B9: AGO | D9: 2021 | E9: Central government (budgetary) | F9: 0.10724204 | G9: 0.23824708 | H9: 0.079403848 | I9: 0.072294254 | J9: 0.2474218 | K9: 0.00036318822 | L9: 0.074011318 | M9: =SUM(S9:Y9) -> 0.078667505 | N9: 0.0052639513 | O9: 0.073520325 | P9: 0.023564694 | R9: =SUM(F9:Q9) -> 1 | S9: 0.00058143111 | T9: 3.4666817e-05 | U9: 0.040951099 | V9: 0.037100309 | W9: 0 | X9: 0 | Z9: =IFERROR(IF(INDEX('All GHED Countries'!$D$5:$AB$199,MATCH($B9,'All GHED Countries'!$B$5:$B$199,0),MATCH($D9,'All GHED Countries'!$D$4:$AB$4,0))="","",INDEX('All GHED Countries'!$D$5:$AB$199,MATCH($B9,'All GHED Countries'!$B$5:$B$199,0),MATCH($D9,'All GHED Countries'!$D$4:$AB$4,0))),"") -> 0.087773657
A10: Azerbaijan | B10: AZE | D10: 2008 | E10: General government | F10: 0.075420433 | G10: 0.00271703 | H10: 0.1099774 | I10: 0.045840534 | J10: 0.41322122 | K10: 0.00081427812 | L10: 0.015895041 | M10: =SUM(S10:Y10) -> 0.029771005 | N10: 0.012180936 | O10: 0.08504221 | P10: 0.18692668 | Q10: 0.022193233 | R10: =SUM(F10:Q10) -> 1 | T10: 0.0049022866 | U10: 0.01694197 | V10: 0 | Y10: 0.0079267482 | Z10: =IFERROR(IF(INDEX('All GHED Countries'!$D$5:$AB$199,MATCH($B10,'All GHED Countries'!$B$5:$B$199,0),MATCH($D10,'All GHED Countries'!$D$4:$AB$4,0))="","",INDEX('All GHED Countries'!$D$5:$AB$199,MATCH($B10,'All GHED Countries'!$B$5:$B$199,0),MATCH($D10,'All GHED Countries'!$D$4:$AB$4,0))),"") -> 0.027519121
A11: Azerbaijan | B11: AZE | D11: 2009 | E11: General government | F11: 0.058362049 | G11: 0.0065822488 | H11: 0.099252283 | I11: 0.056237664 | J11: 0.34660935 | K11: 0.00092000937 | L11: 0.018768191 | M11: =SUM(S11:Y11) -> 0.034600716 | N11: 0.013724867 | O11: 0.10045666 | P11: 0.22933324 | Q11: 0.035152722 | R11: =SUM(F11:Q11) -> 1 | T11: 0.0053695092 | U11: 0.019796929 | V11: 0.00070255261 | Y11: 0.0087317253 | Z11: =IFERROR(IF(INDEX('All GHED Countries'!$D$5:$AB$199,MATCH($B11,'All GHED Countries'!$B$5:$B$199,0),MATCH($D11,'All GHED Countries'!$D$4:$AB$4,0))="","",INDEX('All GHED Countries'!$D$5:$AB$199,MATCH($B11,'All GHED Countries'!$B$5:$B$199,0),MATCH($D11,'All GHED Countries'!$D$4:$AB$4,0))),"") -> 0.032848394
A12: Azerbaijan | B12: AZE | D12: 2010 | E12: General government | F12: 0.10024623 | G12: 0.0029473213 | H12: 0.088680794 | I12: 0.051805701 | J12: 0.35646172 | K12: 0.00085061931 | L12: 0.016094613 | M12: =SUM(S12:Y12) -> 0.032786151 | N12: 0.013072676 | O12: 0.091866886 | P12: 0.21695269 | Q12: 0.028234592 | R12: =SUM(F12:Q12) -> 1 | T12: 0.0058051037 | U12: 0.018079391 | V12: 0.00036561707 | Y12: 0.0085360394 | Z12: =IFERROR(IF(INDEX('All GHED Countries'!$D$5:$AB$199,MATCH($B12,'All GHED Countries'!$B$5:$B$199,0),MATCH($D12,'All GHED Countries'!$D$4:$AB$4,0))="","",INDEX('All GHED Countries'!$D$5:$AB$199,MATCH($B12,'All GHED Countries'!$B$5:$B$199,0),MATCH($D12,'All GHED Countries'!$D$4:$AB$4,0))),"") -> 0.031712611
A13: Azerbaijan | B13: AZE | D13: 2011 | E13: General government | F13: 0.096102761 | G13: 0.0099367353 | H13: 0.079025169 | I13: 0.043209566 | J13: 0.41962786 | K13: 0.00070892982 | L13: 0.0194985 | M13: =SUM(S13:Y13) -> 0.029698886 | N13: 0.011588952 | O13: 0.0777655 | P13: 0.21283714 | R13: =SUM(F13:Q13) -> 1 | T13: 0.0050445337 | U13: 0.016129618 | V13: 0.00028122836 | Y13: 0.0082435063 | Z13: =IFERROR(IF(INDEX('All GHED Countries'!$D$5:$AB$199,MATCH($B13,'All GHED Countries'!$B$5:$B$199,0),MATCH($D13,'All GHED Countries'!$D$4:$AB$4,0))="","",INDEX('All GHED Countries'!$D$5:$AB$199,MATCH($B13,'All GHED Countries'!$B$5:$B$199,0),MATCH($D13,'All GHED Countries'!$D$4:$AB$4,0))),"") -> 0.028160138
A14: Azerbaijan | B14: AZE | D14: 2012 | E14: General government | F14: 0.13359159 | G14: 0.0046097787 | H14: 0.071783759 | I14: 0.049322587 | J14: 0.37748057 | K14: 0.00064393804 | L14: 0.023631504 | M14: =SUM(S14:Y14) -> 0.031834048 | N14: 0.01271011 | O14: 0.077379888 | P14: 0.21701223 | R14: =SUM(F14:Q14) -> 1 | T14: 0.0048244247 | U14: 0.01658907 | V14: 0.00025042035 | Y14: 0.010170133 | Z14: =IFERROR(IF(INDEX('All GHED Countries'!$D$5:$AB$199,MATCH($B14,'All GHED Countries'!$B$5:$B$199,0),MATCH($D14,'All GHED Countries'!$D$4:$AB$4,0))="","",INDEX('All GHED Countries'!$D$5:$AB$199,MATCH($B14,'All GHED Countries'!$B$5:$B$199,0),MATCH($D14,'All GHED Countries'!$D$4:$AB$4,0))),"") -> 0.030453246
A15: Azerbaijan | B15: AZE | D15: 2013 | E15: General government | F15: 0.094873076 | G15: 0.0075036281 | H15: 0.070906193 | I15: 0.051692718 | J15: 0.43187496 | K15: 0.0006756596 | L15: 0.020545762 | M15: =SUM(S15:Y15) -> 0.030095401 | N15: 0.013479885 | O15: 0.071186925 | P15: 0.2071658 | R15: =SUM(F15:Q15) -> 1 | T15: 0.0046344539 | U15: 0.015640092 | V15: 0.00025694097 | Y15: 0.0095639141 | Z15: =IFERROR(IF(INDEX('All GHED Countries'!$D$5:$AB$199,MATCH($B15,'All GHED Countries'!$B$5:$B$199,0),MATCH($D15,'All GHED Countries'!$D$4:$AB$4,0))="","",INDEX('All GHED Countries'!$D$5:$AB$199,MATCH($B15,'All GHED Countries'!$B$5:$B$199,0),MATCH($D15,'All GHED Countries'!$D$4:$AB$4,0))),"") -> 0.028222861
A16: Azerbaijan | B16: AZE | D16: 2014 | E16: General government | F16: 0.16142488 | G16: 0.0040093138 | H16: 0.072472394 | I16: 0.054530477 | J16: 0.38445605 | K16: 0.0007142483 | L16: 0.021489351 | M16: =SUM(S16:Y16) -> 0.032603054 | N16: 0.014442101 | O16: 0.076995967 | P16: 0.17686216 | R16: =SUM(F16:Q16) -> 1 | T16: 0.0050711629 | U16: 0.017337187 | V16: 0.00031426925 | Y16: 0.0098804348 | Z16: =IFERROR(IF(INDEX('All GHED Countries'!$D$5:$AB$199,MATCH($B16,'All GHED Countries'!$B$5:$B$199,0),MATCH($D16,'All GHED Countries'!$D$4:$AB$4,0))="","",INDEX('All GHED Countries'!$D$5:$AB$199,MATCH($B16,'All GHED Countries'!$B$5:$B$199,0),MATCH($D16,'All GHED Countries'!$D$4:$AB$4,0))),"") -> 0.031070068
